Workbook

Sheet ACTUAL_DATASET
A1: Patient ID | B1: Age | C1: Systolic BP | D1: Diastolic BP | E1: Diabetes | F1: BMI | G1: Smoking | H1: Disease(Actual)
A2: 1 | B2: 45 | C2: 130 | D2: 85 | E2: Yes | F2: 28.5 | G2: No | H2: Heart Disease | L2: SUMMARY TABLE
A3: 2 | B3: 60 | C3: 150 | D3: 95 | E3: Yes | F3: 31.2 | G3: Yes | H3: Heart Disease | K3: Actual cases of Heart Disease | L3: =COUNTIF(H2:H33,"Heart Disease") -> 23
A4: 3 | B4: 35 | C4: 120 | D4: 80 | E4: No | F4: 24.1 | G4: No | H4: No Disease | K4: Total patients | L4: 32
A5: 4 | B5: 50 | C5: 140 | D5: 90 | E5: Yes | F5: 29.8 | G5: No | H5: Heart Disease
A6: 5 | B6: 28 | C6: 110 | D6: 70 | E6: No | F6: 22.5 | G6: No | H6: No Disease
A7: 6 | B7: 53 | C7: 125 | D7: 79 | E7: No | F7: 26.4 | G7: No | H7: Heart Disease
A8: 7 | B8: 51 | C8: 120 | D8: 74 | E8: No | F8: 31 | G8: Yes | H8: Heart Disease
A9: 8 | B9: 50 | C9: 114 | D9: 74 | E9: No | F9: 19.3 | G9: Yes | H9: Heart Disease
A10: 9 | B10: 39 | C10: 153 | D10: 99 | E10: No | F10: 18.4 | G10: Yes | H10: Heart Disease | K10: Age Groups | L10: Count of Disease(Actual)
A11: 10 | B11: 34 | C11: 123 | D11: 77 | E11: Yes | F11: 28.5 | G11: No | H11: No Disease | K11: 20-29 | L11: 3
A12: 11 | B12: 35 | C12: 118 | D12: 77 | E12: No | F12: 26.4 | G12: Yes | H12: No Disease | K12: 30-39 | L12: 7
A13: 12 | B13: 50 | C13: 135 | D13: 87 | E13: No | F13: 19.2 | G13: Yes | H13: Heart Disease | K13: 40-49 | L13: 3
A14: 13 | B14: 35 | C14: 114 | D14: 69 | E14: Yes | F14: 20.7 | G14: No | H14: No Disease | K14: 50-59 | L14: 15
A15: 14 | B15: 51 | C15: 129 | D15: 85 | E15: Yes | F15: 25.5 | G15: No | H15: Heart Disease | K15: 60-70 | L15: 4
A16: 15 | B16: 54 | C16: 126 | D16: 78 | E16: No | F16: 30.6 | G16: No | H16: Heart Disease
A17: 16 | B17: 51 | C17: 124 | D17: 74 | E17: Yes | F17: 30.9 | G17: Yes | H17: Heart Disease
A18: 17 | B18: 58 | C18: 141 | D18: 93 | E18: No | F18: 28.2 | G18: Yes | H18: Heart Disease
A19: 18 | B19: 47 | C19: 126 | D19: 79 | E19: No | F19: 33.3 | G19: No | H19: Heart Disease
A20: 19 | B20: 58 | C20: 130 | D20: 86 | E20: Yes | F20: 27.1 | G20: No | H20: Heart Disease
A21: 20 | B21: 38 | C21: 133 | D21: 86 | E21: No | F21: 25 | G21: No | H21: No Disease
A22: 21 | B22: 64 | C22: 129 | D22: 81 | E22: No | F22: 27.7 | G22: No | H22: Heart Disease
A23: 22 | B23: 51 | C23: 120 | D23: 75 | E23: Yes | F23: 28 | G23: No | H23: Heart Disease
A24: 23 | B24: 53 | C24: 126 | D24: 86 | E24: Yes | F24: 26.3 | G24: No | H24: No Disease
A25: 24 | B25: 24 | C25: 127 | D25: 91 | E25: Yes | F25: 26.9 | G25: Yes | H25: Heart Disease
A26: 25 | B26: 53 | C26: 142 | D26: 90 | E26: Yes | F26: 26 | G26: Yes | H26: Heart Disease | K26: SYSTOLIC BP(mm Hg) | L26: Count of Disease(Actual)
A27: 26 | B27: 61 | C27: 158 | D27: 95 | E27: Yes | F27: 30 | G27: No | H27: Heart Disease | K27: 100-109 | L27: 1
A28: 27 | B28: 37 | C28: 142 | D28: 94 | E28: No | F28: 27.3 | G28: No | H28: Heart Disease | K28: 110-119 | L28: 4
A29: 28 | B29: 29 | C29: 107 | D29: 74 | E29: No | F29: 27.3 | G29: Yes | H29: No Disease | K29: 120-129 | L29: 13
A30: 29 | B30: 43 | C30: 129 | D30: 84 | E30: Yes | F30: 23.5 | G30: No | H30: No Disease | K30: 130-139 | L30: 6
A31: 30 | B31: 50 | C31: 130 | D31: 86 | E31: No | F31: 32.2 | G31: Yes | H31: Heart Disease | K31: 140-149 | L31: 4
A32: 31 | B32: 63 | C32: 139 | D32: 93 | E32: No | F32: 23.5 | G32: No | H32: Heart Disease | K32: 150-160 | L32: 4
A33: 32 | B33: 51 | C33: 159 | D33: 103 | E33: Yes | F33: 24.1 | G33: Yes | H33: Heart Disease
K42: DIASTOLIC BP(mm Hg) | L42: Count of Disease(Actual)
K43: 65-74 | L43: 6
K44: 75-84 | L44: 9
K45: 85-94 | L45: 13
K46: 95-105 | L46: 4
K60: BMI | L60: Count of Disease(Actual)
K61: 18-23 | L61: 5
...

Sheet LOGISTIC_REGRESSION&EVALUATION
A2: SUMMARY OUTPUT | L2: SUMMARY TABLE FOR LOGISTIC REGRESSION
L3: PREDICTED HEART DISEASE | M3: =COUNTIF(K31:K62,"Heart Disease") -> 4
A4: Regression Statistics | L4: PREDICTED NO DISEASE | M4: =COUNTIF(K31:K62,"No Disease") -> 28
A5: Multiple R | B5: 0.71609225
A6: R Square | B6: 0.51278811
A7: Adjusted R Square | B7: 0.39585726
A8: Standard Error | B8: 0.35505785
A9: Observations | B9: 32
A11: ANOVA
B12: df | C12: SS | D12: MS | E12: F | F12: Significance F
A13: Regression | B13: 6 | C13: 3.3170981 | D13: 0.55284968 | E13: 4.3853961 | F13: 0.0036958327
A14: Residual | B14: 25 | C14: 3.1516519 | D14: 0.12606608
A15: Total | B15: 31 | C15: 6.46875
B17: Regression Coefficients | C17: Standard Error | D17: t Stat | E17: P-value | F17: Lower 95% | G17: Upper 95% | H17: Lower 95.0% | I17: Upper 95.0%
A18: Intercept | B18: -2.0155938 | C18: 0.80062142 | D18: -2.5175367 | E18: 0.018595289 | F18: -3.6645045 | G18: -0.36668311 | H18: -3.6645045 | I18: -0.36668311
A19: Age | B19: 0.02066699 | C19: 0.0074570942 | D19: 2.7714536 | E19: 0.010381055 | F19: 0.0053088172 | G19: 0.036025163 | H19: 0.0053088172 | I19: 0.036025163
A20: Systolic BP | B20: 0.0049901398 | C20: 0.015255118 | D20: 0.3271125 | E20: 0.74630602 | F20: -0.026428364 | G20: 0.036408643 | H20: -0.026428364 | I20: 0.036408643
A21: Diastolic BP | B21: 0.0066079908 | C21: 0.021286772 | D21: 0.3104271 | E21: 0.75880945 | F21: -0.037232937 | G21: 0.050448918 | H21: -0.037232937 | I21: 0.050448918
A22: Diabetes | B22: -0.058185521 | C22: 0.13298193 | D22: -0.43754458 | E22: 0.66547325 | F22: -0.33206693 | G22: 0.21569589 | H22: -0.33206693 | I22: 0.21569589
A23: BMI | B23: 0.019022687 | C23: 0.017798725 | D23: 1.0687669 | E23: 0.29538631 | F23: -0.017634473 | G23: 0.055679848 | H23: -0.017634473 | I23: 0.055679848
A24: Smoking | B24: 0.20153699 | C24: 0.13298489 | D24: 1.5154879 | E24: 0.14219183 | F24: -0.072350521 | G24: 0.47542449 | H24: -0.072350521 | I24: 0.47542449
A25: Threshold[predict Heart Disease if probability>= this ] | E25: 0.75
A29: PREDICTIONS PER PATIENT
A30: Patient ID | B30: Age | C30: Systolic BP | D30: Diastolic BP | E30: Diabetes | F30: BMI | G30: Smoking | H30: Z [linear score] | I30: Predicted probability | J30: Disease(Actual) | K30: Predicted | L30: PREDICTED BINARY | M30: Disease (Actual) | N30: Predicted=Actual?
A31: 1 | B31: 45 | C31: 130 | D31: 85 | E31: =IF(ACTUAL_DATASET!E2="Yes", 1,0) -> 1 | F31: 28.5 | G31: =IF(ACTUAL_DATASET!G2="Yes",1,0) -> 0 | H31: {='LOGISTIC_REGRESSION&EVALUATION'!$B$18+SUMPRODUCT( B31:G31, TRANSPOSE('LOGISTIC_REGRESSION&EVALUATION'!$B$19:$B$24))} -> 0.60877924 | I31: =1/(1+EXP(-H31)) -> 0.64766228 | J31: =IF(ACTUAL_DATASET!H2="Heart Disease", 1,0) -> 1 | K31: =IF(I31>=0.75, "Heart Disease","No Disease") -> No Disease | L31: =IF(I31>=0.75,1,0) -> 0 | M31: Heart Disease | N31: =IF(K31=M31,"Yes-1","No-0") -> No-0
A32: 2 | B32: 60 | C32: 150 | D32: 95 | E32: =IF(ACTUAL_DATASET!E3="Yes", 1,0) -> 1 | F32: 31.2 | G32: =IF(ACTUAL_DATASET!G3="Yes",1,0) -> 1 | H32: {='LOGISTIC_REGRESSION&EVALUATION'!$B$18+SUMPRODUCT( B32:G32, TRANSPOSE('LOGISTIC_REGRESSION&EVALUATION'!$B$19:$B$24))} -> 1.337565 | I32: =1/(1+EXP(-H32)) -> 0.79208923 | J32: =IF(ACTUAL_DATASET!H3="Heart Disease", 1,0) -> 1 | K32: =IF(I32>=0.75, "Heart Disease","No Disease") -> Heart Disease | L32: =IF(I32>=0.75,1,0) -> 1 | M32: Heart Disease | N32: =IF(K32=M32,"Yes-1","No-0") -> Yes-1
A33: 3 | B33: 35 | C33: 120 | D33: 80 | E33: =IF(ACTUAL_DATASET!E4="Yes", 1,0) -> 0 | F33: 24.1 | G33: =IF(ACTUAL_DATASET!G4="Yes",1,0) -> 0 | H33: {='LOGISTIC_REGRESSION&EVALUATION'!$B$18+SUMPRODUCT( B33:G33, TRANSPOSE('LOGISTIC_REGRESSION&EVALUATION'!$B$19:$B$24))} -> 0.29365368 | I33: =1/(1+EXP(-H33)) -> 0.57289038 | J33: =IF(ACTUAL_DATASET!H4="Heart Disease", 1,0) -> 0 | K33: =IF(I33>=0.75, "Heart Disease","No Disease") -> No Disease | L33: =IF(I33>=0.75,1,0) -> 0 | M33: No Disease | N33: =IF(K33=M33,"Yes-1","No-0") -> Yes-1
A34: 4 | B34: 50 | C34: 140 | D34: 90 | E34: =IF(ACTUAL_DATASET!E5="Yes", 1,0) -> 1 | F34: 29.8 | G34: =IF(ACTUAL_DATASET!G5="Yes",1,0) -> 0 | H34: {='LOGISTIC_REGRESSION&EVALUATION'!$B$18+SUMPRODUCT( B34:G34, TRANSPOSE('LOGISTIC_REGRESSION&EVALUATION'!$B$19:$B$24))} -> 0.81978503 | I34: =1/(1+EXP(-H34)) -> 0.69419071 | J34: =IF(ACTUAL_DATASET!H5="Heart Disease", 1,0) -> 1 | K34: =IF(I34>=0.75, "Heart Disease","No Disease") -> No Disease | L34: =IF(I34>=0.75,1,0) -> 0 | M34: Heart Disease | N34: =IF(K34=M34,"Yes-1","No-0") -> No-0
A35: 5 | B35: 28 | C35: 110 | D35: 70 | E35: =IF(ACTUAL_DATASET!E6="Yes", 1,0) -> 0 | F35: 22.5 | G35: =IF(ACTUAL_DATASET!G6="Yes",1,0) -> 0 | H35: {='LOGISTIC_REGRESSION&EVALUATION'!$B$18+SUMPRODUCT( B35:G35, TRANSPOSE('LOGISTIC_REGRESSION&EVALUATION'!$B$19:$B$24))} -> 0.0025671424 | I35: =1/(1+EXP(-H35)) -> 0.50064179 | J35: =IF(ACTUAL_DATASET!H6="Heart Disease", 1,0) -> 0 | K35: =IF(I35>=0.75, "Heart Disease","No Disease") -> No Disease | L35: =IF(I35>=0.75,1,0) -> 0 | M35: No Disease | N35: =IF(K35=M35,"Yes-1","No-0") -> Yes-1
A36: 6 | B36: 53 | C36: 125 | D36: 79 | E36: =IF(ACTUAL_DATASET!E7="Yes", 1,0) -> 0 | F36: 26.4 | G36: =IF(ACTUAL_DATASET!G7="Yes",1,0) -> 0 | H36: {='LOGISTIC_REGRESSION&EVALUATION'!$B$18+SUMPRODUCT( B36:G36, TRANSPOSE('LOGISTIC_REGRESSION&EVALUATION'!$B$19:$B$24))} -> 0.72775439 | I36: =1/(1+EXP(-H36)) -> 0.6743123 | J36: =IF(ACTUAL_DATASET!H7="Heart Disease", 1,0) -> 1 | K36: =IF(I36>=0.75, "Heart Disease","No Disease") -> No Disease | L36: =IF(I36>=0.75,1,0) -> 0 | M36: Heart Disease | N36: =IF(K36=M36,"Yes-1","No-0") -> No-0
A37: 7 | B37: 51 | C37: 120 | D37: 74 | E37: =IF(ACTUAL_DATASET!E8="Yes", 1,0) -> 0 | F37: 31 | G37: =IF(ACTUAL_DATASET!G8="Yes",1,0) -> 1 | H37: {='LOGISTIC_REGRESSION&EVALUATION'!$B$18+SUMPRODUCT( B37:G37, TRANSPOSE('LOGISTIC_REGRESSION&EVALUATION'!$B$19:$B$24))} -> 0.91747111 | I37: =1/(1+EXP(-H37)) -> 0.71452655 | J37: =IF(ACTUAL_DATASET!H8="Heart Disease", 1,0) -> 1 | K37: =IF(I37>=0.75, "Heart Disease","No Disease") -> No Disease | L37: =IF(I37>=0.75,1,0) -> 0 | M37: Heart Disease | N37: =IF(K37=M37,"Yes-1","No-0") -> No-0
A38: 8 | B38: 50 | C38: 114 | D38: 74 | E38: =IF(ACTUAL_DATASET!E9="Yes", 1,0) -> 0 | F38: 19.3 | G38: =IF(ACTUAL_DATASET!G9="Yes",1,0) -> 1 | H38: {='LOGISTIC_REGRESSION&EVALUATION'!$B$18+SUMPRODUCT( B38:G38, TRANSPOSE('LOGISTIC_REGRESSION&EVALUATION'!$B$19:$B$24))} -> 0.64429784 | I38: =1/(1+EXP(-H38)) -> 0.65572435 | J38: =IF(ACTUAL_DATASET!H9="Heart Disease", 1,0) -> 1 | K38: =IF(I38>=0.75, "Heart Disease","No Disease") -> No Disease | L38: =IF(I38>=0.75,1,0) -> 0 | M38: Heart Disease | N38: =IF(K38=M38,"Yes-1","No-0") -> No-0
A39: 9 | B39: 39 | C39: 153 | D39: 99 | E39: =IF(ACTUAL_DATASET!E10="Yes", 1,0) -> 0 | F39: 18.4 | G39: =IF(ACTUAL_DATASET!G10="Yes",1,0) -> 1 | H39: {='LOGISTIC_REGRESSION&EVALUATION'!$B$18+SUMPRODUCT( B39:G39, TRANSPOSE('LOGISTIC_REGRESSION&EVALUATION'!$B$19:$B$24))} -> 0.75965575 | I39: =1/(1+EXP(-H39)) -> 0.68127899 | J39: =IF(ACTUAL_DATASET!H10="Heart Disease", 1,0) -> 1 | K39: =IF(I39>=0.75, "Heart Disease","No Disease") -> No Disease | L39: =IF(I39>=0.75,1,0) -> 0 | M39: Heart Disease | N39: =IF(K39=M39,"Yes-1","No-0") -> No-0
A40: 10 | B40: 34 | C40: 123 | D40: 77 | E40: =IF(ACTUAL_DATASET!E11="Yes", 1,0) -> 1 | F40: 28.5 | G40: =IF(ACTUAL_DATASET!G11="Yes",1,0) -> 0 | H40: {='LOGISTIC_REGRESSION&EVALUATION'!$B$18+SUMPRODUCT( B40:G40, TRANSPOSE('LOGISTIC_REGRESSION&EVALUATION'!$B$19:$B$24))} -> 0.29364744 | I40: =1/(1+EXP(-H40)) -> 0.57288885 | J40: =IF(ACTUAL_DATASET!H11="Heart Disease", 1,0) -> 0 | K40: =IF(I40>=0.75, "Heart Disease","No Disease") -> No Disease | L40: =IF(I40>=0.75,1,0) -> 0 | M40: No Disease | N40: =IF(K40=M40,"Yes-1","No-0") -> Yes-1
A41: 11 | B41: 35 | C41: 118 | D41: 77 | E41: =IF(ACTUAL_DATASET!E12="Yes", 1,0) -> 0 | F41: 26.4 | G41: =IF(ACTUAL_DATASET!G12="Yes",1,0) -> 1 | H41: {='LOGISTIC_REGRESSION&EVALUATION'!$B$18+SUMPRODUCT( B41:G41, TRANSPOSE('LOGISTIC_REGRESSION&EVALUATION'!$B$19:$B$24))} -> 0.5091386 | I41: =1/(1+EXP(-H41)) -> 0.62460452 | J41: =IF(ACTUAL_DATASET!H12="Heart Disease", 1,0) -> 0 | K41: =IF(I41>=0.75, "Heart Disease","No Disease") -> No Disease | L41: =IF(I41>=0.75,1,0) -> 0 | M41: No Disease | N41: =IF(K41=M41,"Yes-1","No-0") -> Yes-1
A42: 12 | B42: 50 | C42: 135 | D42: 87 | E42: =IF(ACTUAL_DATASET!E13="Yes", 1,0) -> 0 | F42: 19.2 | G42: =IF(ACTUAL_DATASET!G13="Yes",1,0) -> 1 | H42: {='LOGISTIC_REGRESSION&EVALUATION'!$B$18+SUMPRODUCT( B42:G42, TRANSPOSE('LOGISTIC_REGRESSION&EVALUATION'!$B$19:$B$24))} -> 0.83309238 | I42: =1/(1+EXP(-H42)) -> 0.6970084 | J42: =IF(ACTUAL_DATASET!H13="Heart Disease", 1,0) -> 1 | K42: =IF(I42>=0.75, "Heart Disease","No Disease") -> No Disease | L42: =IF(I42>=0.75,1,0) -> 0 | M42: Heart Disease | N42: =IF(K42=M42,"Yes-1","No-0") -> No-0
... A62: 32 | B62: 51 | C62: 159 | D62: 103 | E62: =IF(ACTUAL_DATASET!E33="Yes", 1,0) -> 1 | F62: 24.1 | G62: =IF(ACTUAL_DATASET!G33="Yes",1,0) -> 1 | H62: {='LOGISTIC_REGRESSION&EVALUATION'!$B$18+SUMPRODUCT( B62:G62, TRANSPOSE('LOGISTIC_REGRESSION&EVALUATION'!$B$19:$B$24))} -> 1.1142762 | I62: =1/(1+EXP(-H62)) -> 0.75292547 | J62: =IF(ACTUAL_DATASET!H33="Heart Disease", 1,0) -> 1 | K62: =IF(I62>=0.75, "Heart Disease","No Disease") -> Heart Disease | L62: =IF(I62>=0.75,1,0) -> 1 | M62: Heart Disease | N62: =IF(K62=M62,"Yes-1","No-0") -> Yes-1
A66: CONFUSION MATRIX | B66: PREDICTED POSITIVE(1) | C66: PREDICTED NEGATIVE(0) | H66: CONFUSION MATRIX | I66: PREDICTED POSITIVE(1) | J66: PREDICTED NEGATIVE(0)
A67: ACTUAL POSITIVE(1) | B67: TRUE POSITIVE(TP) | C67: FALSE NEGATIVE(FN) | H67: ACTUAL POSITIVE(1) | I67: =COUNTIFS(J31:J62,1, L31:L62,1) -> 4 | J67: =COUNTIFS(J31:J62,1,L31:L62,0) -> 19
A68: ACTUAL NEGATIVE(0) | B68: FALSE POSITIVE(FP) | C68: TRUE NEGATIVE(TN) | H68: ACTUAL NEGATIVE(0) | I68: =COUNTIFS(J31:J62,0,L31:L62,1) -> 0 | J68: =COUNTIFS(J31:J62,0,L31:L62,0) -> 9
...

Sheet DECISION_TREE
A1: PREDICTION PER PATIENT
A2: Patient ID | B2: Age | C2: Systolic BP | D2: Diastolic BP | E2: Diabetes | F2: BMI | G2: Smoking | H2: Predicted | I2: Disease(Actual) | J2: ACTUAL=PREDICTED?
A3: 1 | B3: 45 | C3: 130 | D3: 85 | E3: Yes | F3: 28.5 | G3: No | H3: {=_xlfn.IFS(B3<=N$4,"No Disease", F3>N$5,"Heart Disease", G3=N$6, "Heart Disease", TRUE,"No Disease")} -> Heart Disease | I3: Heart Disease | J3: =IF(H3=I3,"Yes-1","No-0") -> Yes-1 | M3: DECISION RULES
A4: 2 | B4: 60 | C4: 150 | D4: 95 | E4: Yes | F4: 31.2 | G4: Yes | H4: {=_xlfn.IFS(B4<=N$4,"No Disease", F4>N$5,"Heart Disease", G4=N$6, "Heart Disease", TRUE,"No Disease")} -> Heart Disease | I4: Heart Disease | J4: =IF(H4=I4,"Yes-1","No-0") -> Yes-1 | M4: If Age ≤ | N4: 36 | O4: → predict No Disease
A5: 3 | B5: 35 | C5: 120 | D5: 80 | E5: No | F5: 24.1 | G5: No | H5: {=_xlfn.IFS(B5<=N$4,"No Disease", F5>N$5,"Heart Disease", G5=N$6, "Heart Disease", TRUE,"No Disease")} -> No Disease | I5: No Disease | J5: =IF(H5=I5,"Yes-1","No-0") -> Yes-1 | M5: Else if BMI > | N5: 25.25 | O5: → predict Heart Disease
A6: 4 | B6: 50 | C6: 140 | D6: 90 | E6: Yes | F6: 29.8 | G6: No | H6: {=_xlfn.IFS(B6<=N$4,"No Disease", F6>N$5,"Heart Disease", G6=N$6, "Heart Disease", TRUE,"No Disease")} -> Heart Disease | I6: Heart Disease | J6: =IF(H6=I6,"Yes-1","No-0") -> Yes-1 | M6: Else if Smoking | N6: Yes | O6: → predict Heart Disease
A7: 5 | B7: 28 | C7: 110 | D7: 70 | E7: No | F7: 22.5 | G7: No | H7: {=_xlfn.IFS(B7<=N$4,"No Disease", F7>N$5,"Heart Disease", G7=N$6, "Heart Disease", TRUE,"No Disease")} -> No Disease | I7: No Disease | J7: =IF(H7=I7,"Yes-1","No-0") -> Yes-1 | M7: Otherwise | O7: → predict No Disease
A8: 6 | B8: 53 | C8: 125 | D8: 79 | E8: No | F8: 26.4 | G8: No | H8: {=_xlfn.IFS(B8<=N$4,"No Disease", F8>N$5,"Heart Disease", G8=N$6, "Heart Disease", TRUE,"No Disease")} -> Heart Disease | I8: Heart Disease | J8: =IF(H8=I8,"Yes-1","No-0") -> Yes-1
A9: 7 | B9: 51 | C9: 120 | D9: 74 | E9: No | F9: 31 | G9: Yes | H9: {=_xlfn.IFS(B9<=N$4,"No Disease", F9>N$5,"Heart Disease", G9=N$6, "Heart Disease", TRUE,"No Disease")} -> Heart Disease | I9: Heart Disease | J9: =IF(H9=I9,"Yes-1","No-0") -> Yes-1
A10: 8 | B10: 50 | C10: 114 | D10: 74 | E10: No | F10: 19.3 | G10: Yes | H10: {=_xlfn.IFS(B10<=N$4,"No Disease", F10>N$5,"Heart Disease", G10=N$6, "Heart Disease", TRUE,"No Disease")} -> Heart Disease | I10: Heart Disease | J10: =IF(H10=I10,"Yes-1","No-0") -> Yes-1
A11: 9 | B11: 39 | C11: 153 | D11: 99 | E11: No | F11: 18.4 | G11: Yes | H11: {=_xlfn.IFS(B11<=N$4,"No Disease", F11>N$5,"Heart Disease", G11=N$6, "Heart Disease", TRUE,"No Disease")} -> Heart Disease | I11: Heart Disease | J11: =IF(H11=I11,"Yes-1","No-0") -> Yes-1
A12: 10 | B12: 34 | C12: 123 | D12: 77 | E12: Yes | F12: 28.5 | G12: No | H12: {=_xlfn.IFS(B12<=N$4,"No Disease", F12>N$5,"Heart Disease", G12=N$6, "Heart Disease", TRUE,"No Disease")} -> No Disease | I12: No Disease | J12: =IF(H12=I12,"Yes-1","No-0") -> Yes-1
A13: 11 | B13: 35 | C13: 118 | D13: 77 | E13: No | F13: 26.4 | G13: Yes | H13: {=_xlfn.IFS(B13<=N$4,"No Disease", F13>N$5,"Heart Disease", G13=N$6, "Heart Disease", TRUE,"No Disease")} -> No Disease | I13: No Disease | J13: =IF(H13=I13,"Yes-1","No-0") -> Yes-1
A14: 12 | B14: 50 | C14: 135 | D14: 87 | E14: No | F14: 19.2 | G14: Yes | H14: {=_xlfn.IFS(B14<=N$4,"No Disease", F14>N$5,"Heart Disease", G14=N$6, "Heart Disease", TRUE,"No Disease")} -> Heart Disease | I14: Heart Disease | J14: =IF(H14=I14,"Yes-1","No-0") -> Yes-1
A15: 13 | B15: 35 | C15: 114 | D15: 69 | E15: Yes | F15: 20.7 | G15: No | H15: {=_xlfn.IFS(B15<=N$4,"No Disease", F15>N$5,"Heart Disease", G15=N$6, "Heart Disease", TRUE,"No Disease")} -> No Disease | I15: No Disease | J15: =IF(H15=I15,"Yes-1","No-0") -> Yes-1 | M15: SUMMARY TABLE
A16: 14 | B16: 51 | C16: 129 | D16: 85 | E16: Yes | F16: 25.5 | G16: No | H16: {=_xlfn.IFS(B16<=N$4,"No Disease", F16>N$5,"Heart Disease", G16=N$6, "Heart Disease", TRUE,"No Disease")} -> Heart Disease | I16: Heart Disease | J16: =IF(H16=I16,"Yes-1","No-0") -> Yes-1 | M16: PREDICTED HEART DISEASE | N16: =COUNTIF(H3:H34,"Heart Disease") -> 22
A17: 15 | B17: 54 | C17: 126 | D17: 78 | E17: No | F17: 30.6 | G17: No | H17: {=_xlfn.IFS(B17<=N$4,"No Disease", F17>N$5,"Heart Disease", G17=N$6, "Heart Disease", TRUE,"No Disease")} -> Heart Disease | I17: Heart Disease | J17: =IF(H17=I17,"Yes-1","No-0") -> Yes-1 | M17: PREDICTED NO DISEASE | N17: =COUNTIF(H3:H34,"No Disease") -> 10
A18: 16 | B18: 51 | C18: 124 | D18: 74 | E18: Yes | F18: 30.9 | G18: Yes | H18: {=_xlfn.IFS(B18<=N$4,"No Disease", F18>N$5,"Heart Disease", G18=N$6, "Heart Disease", TRUE,"No Disease")} -> Heart Disease | I18: Heart Disease | J18: =IF(H18=I18,"Yes-1","No-0") -> Yes-1
A19: 17 | B19: 58 | C19: 141 | D19: 93 | E19: No | F19: 28.2 | G19: Yes | H19: {=_xlfn.IFS(B19<=N$4,"No Disease", F19>N$5,"Heart Disease", G19=N$6, "Heart Disease", TRUE,"No Disease")} -> Heart Disease | I19: Heart Disease | J19: =IF(H19=I19,"Yes-1","No-0") -> Yes-1
A20: 18 | B20: 47 | C20: 126 | D20: 79 | E20: No | F20: 33.3 | G20: No | H20: {=_xlfn.IFS(B20<=N$4,"No Disease", F20>N$5,"Heart Disease", G20=N$6, "Heart Disease", TRUE,"No Disease")} -> Heart Disease | I20: Heart Disease | J20: =IF(H20=I20,"Yes-1","No-0") -> Yes-1
A21: 19 | B21: 58 | C21: 130 | D21: 86 | E21: Yes | F21: 27.1 | G21: No | H21: {=_xlfn.IFS(B21<=N$4,"No Disease", F21>N$5,"Heart Disease", G21=N$6, "Heart Disease", TRUE,"No Disease")} -> Heart Disease | I21: Heart Disease | J21: =IF(H21=I21,"Yes-1","No-0") -> Yes-1
A22: 20 | B22: 38 | C22: 133 | D22: 86 | E22: No | F22: 25 | G22: No | H22: {=_xlfn.IFS(B22<=N$4,"No Disease", F22>N$5,"Heart Disease", G22=N$6, "Heart Disease", TRUE,"No Disease")} -> No Disease | I22: No Disease | J22: =IF(H22=I22,"Yes-1","No-0") -> Yes-1
A23: 21 | B23: 64 | C23: 129 | D23: 81 | E23: No | F23: 27.7 | G23: No | H23: {=_xlfn.IFS(B23<=N$4,"No Disease", F23>N$5,"Heart Disease", G23=N$6, "Heart Disease", TRUE,"No Disease")} -> Heart Disease | I23: Heart Disease | J23: =IF(H23=I23,"Yes-1","No-0") -> Yes-1
A24: 22 | B24: 51 | C24: 120 | D24: 75 | E24: Yes | F24: 28 | G24: No | H24: {=_xlfn.IFS(B24<=N$4,"No Disease", F24>N$5,"Heart Disease", G24=N$6, "Heart Disease", TRUE,"No Disease")} -> Heart Disease | I24: Heart Disease | J24: =IF(H24=I24,"Yes-1","No-0") -> Yes-1
A25: 23 | B25: 53 | C25: 126 | D25: 86 | E25: Yes | F25: 26.3 | G25: No | H25: {=_xlfn.IFS(B25<=N$4,"No Disease", F25>N$5,"Heart Disease", G25=N$6, "Heart Disease", TRUE,"No Disease")} -> Heart Disease | I25: No Disease | J25: =IF(H25=I25,"Yes-1","No-0") -> No-0
A26: 24 | B26: 24 | C26: 127 | D26: 91 | E26: Yes | F26: 26.9 | G26: Yes | H26: {=_xlfn.IFS(B26<=N$4,"No Disease", F26>N$5,"Heart Disease", G26=N$6, "Heart Disease", TRUE,"No Disease")} -> No Disease | I26: Heart Disease | J26: =IF(H26=I26,"Yes-1","No-0") -> No-0
A27: 25 | B27: 53 | C27: 142 | D27: 90 | E27: Yes | F27: 26 | G27: Yes | H27: {=_xlfn.IFS(B27<=N$4,"No Disease", F27>N$5,"Heart Disease", G27=N$6, "Heart Disease", TRUE,"No Disease")} -> Heart Disease | I27: Heart Disease | J27: =IF(H27=I27,"Yes-1","No-0") -> Yes-1
A28: 26 | B28: 61 | C28: 158 | D28: 95 | E28: Yes | F28: 30 | G28: No | H28: {=_xlfn.IFS(B28<=N$4,"No Disease", F28>N$5,"Heart Disease", G28=N$6, "Heart Disease", TRUE,"No Disease")} -> Heart Disease | I28: Heart Disease | J28: =IF(H28=I28,"Yes-1","No-0") -> Yes-1
A29: 27 | B29: 37 | C29: 142 | D29: 94 | E29: No | F29: 27.3 | G29: No | H29: {=_xlfn.IFS(B29<=N$4,"No Disease", F29>N$5,"Heart Disease", G29=N$6, "Heart Disease", TRUE,"No Disease")} -> Heart Disease | I29: Heart Disease | J29: =IF(H29=I29,"Yes-1","No-0") -> Yes-1
... A34: 32 | B34: 51 | C34: 159 | D34: 103 | E34: Yes | F34: 24.1 | G34: Yes | H34: {=_xlfn.IFS(B34<=N$4,"No Disease", F34>N$5,"Heart Disease", G34=N$6, "Heart Disease", TRUE,"No Disease")} -> Heart Disease | I34: Heart Disease | J34: =IF(H34=I34,"Yes-1","No-0") -> Yes-1
A40: CONFUSION MATRIX | C40: PREDICTED POSITIVE(1) | D40: PREDICTED NEGATIVE(0) | H40: CONFUSION MATRIX | I40: PREDICTED POSITIVE(1) | J40: PREDICTED NEGATIVE(0)
A41: ACTUAL POSITIVE(1) | C41: TP | D41: FN | H41: ACTUAL POSITIVE(1) | I41: =COUNTIFS(H3:H34,"Heart Disease",I3:I34,"Heart Disease") -> 21 | J41: =COUNTIFS(H3:H34,"No Disease",I3:I34,"Heart Disease") -> 2
A42: ACTUAL NEGATIVE(0) | C42: FP | D42: TN | H42: ACTUAL NEGATIVE(0) | I42: =COUNTIFS(H3:H34,"Heart Disease",I3:I34,"No Disease") -> 1 | J42: =COUNTIFS(H3:H34,"No Disease",I3:I34,"No Disease") -> 8
A44: PERFORMANCE METRICS | B44: FORMULA | C44: DESCRIPTION | H44: PERFORMANCE METRICS OF DECISION TREE MODEL | I44: VALUE | J44: PERCENTAGE
A45: ACCURACY | B45: TP+TN/(TP+TN+FP+FN) | C45: OVERALL CORRECT PREDICTIONS | H45: ACCURACY | I45: =(I41+J42)/32 -> 0.90625 | J45: =I45 -> 0.90625
A46: PRECISION | B46: TP/(TP+FP) | C46: RELIABILITY WHEN MODEL PREDICTS "HEART DISEASE" | H46: PRECISION | I46: =I41/(I41+I42) -> 0.95454545 | J46: =I46 -> 0.95454545
A47: RECALL(SENSITIVITY) | B47: TP/(TP+FN) | C47: PROPORTION OF ACTUAL PATIENTS FLAGGED | H47: RECALL(SENSITIVITY) | I47: =I41/(I41+J41) -> 0.91304348 | J47: =I47 -> 0.91304348
A48: F1 SCORE | B48: 2* (PRECISION*RECALL)/(PRECISION +RECALL) | C48: HARMONIC MEAN OF PRECISION&RECALL | H48: F1 SCORE | I48: =2*(I46*I47)/(I46+I47) -> 0.93333333 | J48: =I48 -> 0.93333333

Sheet PREDICTION_MODEL_NEW_PATIENT
A6: Prediction Model for New Patient
A7: Fill the blue cells
A8: Age (years) | B8: 60 | C8: =B8 -> 60
A9: Systolic BP (mmHg) | B9: 132 | C9: =B9 -> 132
A10: Diastolic BP (mmHg) | B10: 88 | C10: =B10 -> 88
A11: Diabetes | B11: Yes | C11: =IF(B11="Yes",1,0) -> 1
A12: BMI | B12: 29.5 | C12: =B12 -> 29.5
A13: Smoking | B13: No | C13: =IF(B13="Yes",1,0) -> 0
A16: LOGISTIC REGRESSION RESULT
A17: Linear score (Z) | C17: ='LOGISTIC_REGRESSION&EVALUATION'!$B$18 + SUMPRODUCT('LOGISTIC_REGRESSION&EVALUATION'!$B$19:$B$24, PREDICTION_MODEL_NEW_PATIENT!C8:C13) -> 0.96761103
A18: Probabilty of heart disease | C18: =1/(1+EXP(-C17)) -> 0.72464307
A19: Predicted | C19: =IF(C18>=0.75,"Heart Disease", "No disease") -> No disease
A21: DECISION TREE RESULT
A22: Predicted | C22: {=_xlfn.IFS(B8<=L24,"No Disease",B12>=L25,"Heart Disease",B13=L26,"Heart Disease", TRUE,"No Disease")} -> Heart Disease
K23: DECISION RULES
K24: If Age ≤ | L24: 36 | M24: → predict No Disease
K25: Else if BMI > | L25: 25.25 | M25: → predict Heart Disease
K26: Else if Smoking | L26: Yes | M26: → predict Heart Disease
K27: Otherwise | M27: → predict No Disease

Sheet MODEL_OUTPUT
